<?xml version="1.0" ?>
<!-- =================================================================================== -->
<!-- |    This document was autogenerated by xacro from src/ros1_wiki/mobile_robot/urdf/rocky.xacro | -->
<!-- |    EDITING THIS FILE BY HAND IS NOT RECOMMENDED                                 | -->
<!-- =================================================================================== -->
<!-- <robot name="origins"> -->
<robot name="robot">
  <!-- 
  notes:
  - to compile into urdf:
  rosrun xacro xacro -o src/ros1_wiki/mobile_robot/urdf/rocky.urdf   src/ros1_wiki/mobile_robot/urdf/rocky.xacro  
  - to visualize w/ rvis:
  cd ~/catkin_ws
  roslaunch mobile_robot rviz.launch
  -->
  <!-- https://github.com/joshnewans/urdf_example/blob/main/description/example_include.xacro -->
  <material name="white">
    <color rgba="1 1 1 1"/>
  </material>
  <material name="orange">
    <color rgba="1 0.3 0.1 1"/>
  </material>
  <material name="blue">
    <color rgba="0.2 0.2 1 1"/>
  </material>
  <!-- Specify some standard inertial calculations https://en.wikipedia.org/wiki/List_of_moments_of_inertia -->
  <!-- ############################################################################################################################## -->
  <!-- https://answers.ros.org/question/289031/what-is-the-correct-way-to-introduce-a-dummy-link-in-urdf/ -->
  <link name="base_link"/>
  <joint name="base_link_to_left_wheel" type="fixed">
    <parent link="base_link"/>
    <child link="left_wheel"/>
  </joint>
  <!-- <link name="base_link">   -->
  <link name="left_wheel">
    <visual>
      <geometry>
        <cylinder length="0.06" radius="0.15"/>
      </geometry>
      <origin rpy="1.5707963267948966 0 0" xyz="0 0 0.15"/>
      <material name="blue"/>
    </visual>
    <collision>
      <geometry>
        <cylinder length="0.06" radius="0.15"/>
      </geometry>
      <origin rpy="1.5707963267948966 0 0" xyz="0 0 0.15"/>
    </collision>
    <inertial>
      <origin rpy="1.5707963267948966 0 0" xyz="0 0 0.15"/>
      <mass value="100.0"/>
      <inertia ixx="0.005925" ixy="0.0" ixz="0.0" iyy="0.005925" iyz="0.0" izz="0.01125"/>
    </inertial>
  </link>
  <joint name="left_wheel_to_left_shin" type="fixed">
    <!-- <parent link="base_link"/> -->
    <parent link="left_wheel"/>
    <child link="left_shin"/>
    <origin xyz="0 0.03 0.15"/>
    <axis xyz="0 1 0"/>
    <limit effort="0.01" />
  </joint>
  <link name="left_shin">
    <visual>
      <geometry>
        <box size="0.03 0.03 0.6"/>
      </geometry>
      <origin xyz="0 0.015 0.285"/>
      <material name="orange"/>
    </visual>
    <collision>
      <geometry>
        <box size="0.03 0.03 0.6"/>
      </geometry>
      <origin xyz="0 0.015 0.285"/>
    </collision>
    <inertial>
      <origin xyz="0 0.015 0.285"/>
      <mass value="100.0"/>
      <inertia ixx="0.030074999999999998" ixy="0.0" ixz="0.0" iyy="0.030074999999999998" iyz="0.0" izz="0.00015"/>
    </inertial>
  </link>
  <joint name="left_shin_to_left_thigh" type="revolute">
    <parent link="left_shin"/>
    <child link="left_thigh"/>
    <origin xyz="0 0.03 0.57"/>
    <axis xyz="0 1 0"/>
    <limit effort="0.01" lower="0.0" upper="3.141592653589793" />
  </joint>
  <link name="left_thigh">
    <visual>
      <geometry>
        <box size="0.045 0.045 0.45"/>
      </geometry>
      <origin xyz="0 0.0225 0.2025"/>
      <material name="blue"/>
    </visual>
    <collision>
      <geometry>
        <box size="0.045 0.045 0.45"/>
      </geometry>
      <origin xyz="0 0.0225 0.2025"/>
    </collision>
    <inertial>
      <origin xyz="0 0.0225 0.2025"/>
      <mass value="100.0"/>
      <inertia ixx="0.01704375" ixy="0.0" ixz="0.0" iyy="0.01704375" iyz="0.0" izz="0.00033749999999999996"/>
    </inertial>
  </link>
  <joint name="left_thigh_to_left_hip" type="fixed">
    <parent link="left_thigh"/>
    <child link="left_hip"/>
    <origin xyz="0 0.0225 0.405"/>
    <axis xyz="0 1 0"/>
    <limit effort="0.01" />
  </joint>
  <link name="left_hip">
    <visual>
      <geometry>
        <box size="0.055 0.35 0.055"/>
      </geometry>
      <origin xyz="0 0.19749999999999998 0"/>
      <material name="orange"/>
    </visual>
    <collision>
      <geometry>
        <box size="0.055 0.35 0.055"/>
      </geometry>
      <origin xyz="0 0.19749999999999998 0"/>
    </collision>
    <inertial>
      <origin xyz="0 0.19749999999999998 0"/>
      <mass value="100.0"/>
      <inertia ixx="0.010460416666666666" ixy="0.0" ixz="0.0" iyy="0.0005041666666666667" iyz="0.0" izz="0.010460416666666666"/>
    </inertial>
  </link>
  <joint name="left_hip_to_right_hip" type="fixed">
    <parent link="left_hip"/>
    <child link="right_hip"/>
    <origin xyz="0 0.3725 0"/>
    <axis xyz="0 1 0"/>
    <limit effort="0.01" lower="-1.5707963267948966" upper="3.141592653589793" />
  </joint>
  <link name="right_hip">
    <visual>
      <geometry>
        <box size="0.055 0.35 0.055"/>
      </geometry>
      <origin xyz="0 0.175 0"/>
      <material name="blue"/>
    </visual>
    <collision>
      <geometry>
        <box size="0.055 0.35 0.055"/>
      </geometry>
      <origin xyz="0 0.175 0"/>
    </collision>
    <inertial>
      <origin xyz="0 0.175 0"/>
      <mass value="100.0"/>
      <inertia ixx="0.010460416666666666" ixy="0.0" ixz="0.0" iyy="0.0005041666666666667" iyz="0.0" izz="0.010460416666666666"/>
    </inertial>
  </link>
  <joint name="right_hip_to_right_thigh" type="fixed">
    <parent link="right_hip"/>
    <child link="right_thigh"/>
    <origin xyz="0 0.35 0"/>
    <axis xyz="0 1 0"/>
    <limit effort="0.01" />
  </joint>
  <link name="right_thigh">
    <visual>
      <geometry>
        <box size="0.045 0.045 0.45"/>
      </geometry>
      <origin xyz="0 0.0225 -0.2025"/>
      <material name="orange"/>
    </visual>
    <collision>
      <geometry>
        <box size="0.045 0.045 0.45"/>
      </geometry>
      <origin xyz="0 0.0225 -0.2025"/>
    </collision>
    <inertial>
      <origin xyz="0 0.0225 -0.2025"/>
      <mass value="100.0"/>
      <inertia ixx="0.01704375" ixy="0.0" ixz="0.0" iyy="0.01704375" iyz="0.0" izz="0.00033749999999999996"/>
    </inertial>
  </link>
  <joint name="right_thigh_to_right_shin" type="revolute">
    <parent link="right_thigh"/>
    <child link="right_shin"/>
    <origin xyz="0 0.045 -0.405"/>
    <axis xyz="0 1 0"/>
    <limit effort="0.01" lower="0" upper="-3.141592653589793" />
    <!-- todo start here with upper! or these limits! -->
  </joint>
  <link name="right_shin">
    <visual>
      <geometry>
        <box size="0.03 0.03 0.6"/>
      </geometry>
      <origin xyz="0 0.015 -0.285"/>
      <material name="blue"/>
    </visual>
    <collision>
      <geometry>
        <box size="0.03 0.03 0.6"/>
      </geometry>
      <origin xyz="0 0.015 -0.285"/>
    </collision>
    <inertial>
      <origin xyz="0 0.015 -0.285"/>
      <mass value="100.0"/>
      <inertia ixx="0.030074999999999998" ixy="0.0" ixz="0.0" iyy="0.030074999999999998" iyz="0.0" izz="0.00015"/>
    </inertial>
  </link>
  <joint name="right_shin_to_right_wheel" type="fixed">
    <parent link="right_shin"/>
    <child link="right_wheel"/>
    <origin xyz="0 0.03 -0.57"/>
    <axis xyz="0 1 0"/>
    <limit effort="0.01" />
  </joint>
  <link name="right_wheel">
    <visual>
      <geometry>
        <cylinder length="0.06" radius="0.15"/>
      </geometry>
      <origin rpy="1.5707963267948966 0 0" xyz="0 0.03 0"/>
      <material name="orange"/>
    </visual>
    <collision>
      <geometry>
        <cylinder length="0.06" radius="0.15"/>
      </geometry>
      <origin rpy="1.5707963267948966 0 0" xyz="0 0.03 0"/>
    </collision>
    <inertial>
      <origin rpy="1.5707963267948966 0 0" xyz="0 0.03 0"/>
      <mass value="100.0"/>
      <inertia ixx="0.005925" ixy="0.0" ixz="0.0" iyy="0.005925" iyz="0.0" izz="0.01125"/>
    </inertial>
  </link>
</robot>
